<?xml version="1.0" encoding="UTF-8"?>
<!-- Generated by org.testng.reporters.JUnitReportReporter -->
<testsuite skipped="0" hostname="DESKTOP-REH8PLD" name="FtpClientTest" tests="5" failures="0" timestamp="2024-01-30T13:30:56 MSK" time="0.190" errors="1">
  <testcase name="getData_success" time="0.050" classname="FtpClientTest"/>
  <system-out/>
  <testcase name="getData_failIP" time="0.040" classname="FtpClientTest"/>
  <system-out/>
  <testcase name="getData_failPass" time="0.040" classname="FtpClientTest"/>
  <system-out/>
  <testcase name="getData_failConnect" time="0.060" classname="FtpClientTest">
    <error type="org.testng.TestException" message="
Method FtpClientTest.getData_failConnect()[pri:0, instance:FtpClientTest@77b52d12] should have thrown an exception of type class java.net.ConnectException">
      <![CDATA[org.testng.TestException: 
Method FtpClientTest.getData_failConnect()[pri:0, instance:FtpClientTest@77b52d12] should have thrown an exception of type class java.net.ConnectException
at org.testng.internal.invokers.ExpectedExceptionsHolder.noException(ExpectedExceptionsHolder.java:81)
at org.testng.internal.invokers.TestInvoker.considerExceptions(TestInvoker.java:831)
at org.testng.internal.invokers.TestInvoker.invokeMethod(TestInvoker.java:698)
at org.testng.internal.invokers.TestInvoker.invokeTestMethod(TestInvoker.java:219)
at org.testng.internal.invokers.MethodRunner.runInSequence(MethodRunner.java:50)
at org.testng.internal.invokers.TestInvoker$MethodInvocationAgent.invoke(TestInvoker.java:923)
at org.testng.internal.invokers.TestInvoker.invokeTestMethods(TestInvoker.java:192)
at org.testng.internal.invokers.TestMethodWorker.invokeTestMethods(TestMethodWorker.java:146)
at org.testng.internal.invokers.TestMethodWorker.run(TestMethodWorker.java:128)
at java.util.ArrayList.forEach(ArrayList.java:1249)
at org.testng.TestRunner.privateRun(TestRunner.java:808)
at org.testng.TestRunner.run(TestRunner.java:603)
at org.testng.SuiteRunner.runTest(SuiteRunner.java:429)
at org.testng.SuiteRunner.runSequentially(SuiteRunner.java:423)
at org.testng.SuiteRunner.privateRun(SuiteRunner.java:383)
at org.testng.SuiteRunner.run(SuiteRunner.java:326)
at org.testng.SuiteRunnerWorker.runSuite(SuiteRunnerWorker.java:52)
at org.testng.SuiteRunnerWorker.run(SuiteRunnerWorker.java:95)
at org.testng.TestNG.runSuitesSequentially(TestNG.java:1249)
at org.testng.TestNG.runSuitesLocally(TestNG.java:1169)
at org.testng.TestNG.runSuites(TestNG.java:1092)
at org.testng.TestNG.run(TestNG.java:1060)
at RunTest.main(RunTest.java:14)
]]>
    </error>
  </testcase> <!-- getData_failConnect -->
  <system-out/>
  <testcase name="getData_failLogin" time="0.000" classname="FtpClientTest"/>
  <system-out/>
</testsuite> <!-- FtpClientTest -->
